<?xml version="1.0" encoding="UTF-8"?>
<testsuite name="test_vaccine_patient_tests.TestVaccinePatient-20220426161513" tests="6" file="test_vaccine_patient_tests.py" time="0.222" timestamp="2022-04-26T16:15:14" failures="1" errors="4" skipped="0">
	<testcase classname="test_vaccine_patient_tests.TestVaccinePatient" name="test_vaccine_patient_store_date_is_empty" time="0.035" timestamp="2022-04-26T16:15:14"/>
	<testcase classname="test_vaccine_patient_tests.TestVaccinePatient" name="test_vaccine_patient_no_store_date" time="0.036" timestamp="2022-04-26T16:15:14">
		<failure type="AssertionError" message="'date_signature is not found' != 'Store_date not found'
- date_signature is not found
+ Store_date not found
"><![CDATA[Traceback (most recent call last):
  File "C:\Users\beaso\AppData\Local\Programs\Python\Python310\lib\unittest\case.py", line 59, in testPartExecutor
    yield
  File "C:\Users\beaso\AppData\Local\Programs\Python\Python310\lib\unittest\case.py", line 591, in run
    self._callTestMethod(testMethod)
  File "C:\Users\beaso\AppData\Local\Programs\Python\Python310\lib\unittest\case.py", line 549, in _callTestMethod
    method()
  File "C:\Users\beaso\AppData\Local\Programs\Python\Python310\lib\site-packages\freezegun\api.py", line 789, in wrapper
    result = func(*args, **kwargs)
  File "c:\users\beaso\pycharmprojects\g89.2022.t10.eg4\src\unittest\python\test_vaccine_patient_tests.py", line 146, in test_vaccine_patient_no_store_date
    self.assertEqual(context_manager.exception.message, "Store_date not found")
  File "C:\Users\beaso\AppData\Local\Programs\Python\Python310\lib\unittest\case.py", line 845, in assertEqual
    assertion_func(first, second, msg=msg)
  File "C:\Users\beaso\AppData\Local\Programs\Python\Python310\lib\unittest\case.py", line 1226, in assertMultiLineEqual
    self.fail(self._formatMessage(msg, standardMsg))
  File "C:\Users\beaso\AppData\Local\Programs\Python\Python310\lib\unittest\case.py", line 675, in fail
    raise self.failureException(msg)
AssertionError: 'date_signature is not found' != 'Store_date not found'
- date_signature is not found
+ Store_date not found

]]></failure>
	</testcase>
	<testcase classname="test_vaccine_patient_tests.TestVaccinePatient" name="test_vaccine_patient_bad_date_signature" time="0.048" timestamp="2022-04-26T16:15:14">
		<error type="KeyError" message="'VaccinationAppointment__date_signature'"><![CDATA[Traceback (most recent call last):
  File "C:\Users\beaso\AppData\Local\Programs\Python\Python310\lib\unittest\case.py", line 59, in testPartExecutor
    yield
  File "C:\Users\beaso\AppData\Local\Programs\Python\Python310\lib\unittest\case.py", line 591, in run
    self._callTestMethod(testMethod)
  File "C:\Users\beaso\AppData\Local\Programs\Python\Python310\lib\unittest\case.py", line 549, in _callTestMethod
    method()
  File "C:\Users\beaso\AppData\Local\Programs\Python\Python310\lib\site-packages\freezegun\api.py", line 789, in wrapper
    result = func(*args, **kwargs)
  File "c:\users\beaso\pycharmprojects\g89.2022.t10.eg4\src\unittest\python\test_vaccine_patient_tests.py", line 95, in test_vaccine_patient_bad_date_signature
    my_manager.vaccine_patient(
  File "c:\users\beaso\pycharmprojects\g89.2022.t10.eg4\src\main\python\uc3m_care\vaccine_manager.py", line 36, in vaccine_patient
    appointment = VaccinationAppoinment.get_appointment_from_date_signature(date_signature)
  File "c:\users\beaso\pycharmprojects\g89.2022.t10.eg4\src\main\python\uc3m_care\data\vaccination_appointment.py", line 49, in get_appointment_from_date_signature
    appointment_record = appointments_store.find_item(date_signature)
  File "c:\users\beaso\pycharmprojects\g89.2022.t10.eg4\src\main\python\uc3m_care\storage\json_store.py", line 39, in find_item
    if item[key] == key_value:
KeyError: 'VaccinationAppointment__date_signature'
]]></error>
	</testcase>
	<testcase classname="test_vaccine_patient_tests.TestVaccinePatient" name="test_vaccine_patient_no_date" time="0.029" timestamp="2022-04-26T16:15:14">
		<error type="KeyError" message="'VaccinationAppointment__date_signature'"><![CDATA[Traceback (most recent call last):
  File "C:\Users\beaso\AppData\Local\Programs\Python\Python310\lib\unittest\case.py", line 59, in testPartExecutor
    yield
  File "C:\Users\beaso\AppData\Local\Programs\Python\Python310\lib\unittest\case.py", line 591, in run
    self._callTestMethod(testMethod)
  File "C:\Users\beaso\AppData\Local\Programs\Python\Python310\lib\unittest\case.py", line 549, in _callTestMethod
    method()
  File "C:\Users\beaso\AppData\Local\Programs\Python\Python310\lib\site-packages\freezegun\api.py", line 789, in wrapper
    result = func(*args, **kwargs)
  File "c:\users\beaso\pycharmprojects\g89.2022.t10.eg4\src\unittest\python\test_vaccine_patient_tests.py", line 68, in test_vaccine_patient_no_date
    my_manager.vaccine_patient(
  File "c:\users\beaso\pycharmprojects\g89.2022.t10.eg4\src\main\python\uc3m_care\vaccine_manager.py", line 36, in vaccine_patient
    appointment = VaccinationAppoinment.get_appointment_from_date_signature(date_signature)
  File "c:\users\beaso\pycharmprojects\g89.2022.t10.eg4\src\main\python\uc3m_care\data\vaccination_appointment.py", line 49, in get_appointment_from_date_signature
    appointment_record = appointments_store.find_item(date_signature)
  File "c:\users\beaso\pycharmprojects\g89.2022.t10.eg4\src\main\python\uc3m_care\storage\json_store.py", line 39, in find_item
    if item[key] == key_value:
KeyError: 'VaccinationAppointment__date_signature'
]]></error>
	</testcase>
	<testcase classname="test_vaccine_patient_tests.TestVaccinePatient" name="test_vaccine_patient_not_found_date_signature" time="0.039" timestamp="2022-04-26T16:15:14">
		<error type="KeyError" message="'VaccinationAppointment__date_signature'"><![CDATA[Traceback (most recent call last):
  File "C:\Users\beaso\AppData\Local\Programs\Python\Python310\lib\unittest\case.py", line 59, in testPartExecutor
    yield
  File "C:\Users\beaso\AppData\Local\Programs\Python\Python310\lib\unittest\case.py", line 591, in run
    self._callTestMethod(testMethod)
  File "C:\Users\beaso\AppData\Local\Programs\Python\Python310\lib\unittest\case.py", line 549, in _callTestMethod
    method()
  File "C:\Users\beaso\AppData\Local\Programs\Python\Python310\lib\site-packages\freezegun\api.py", line 789, in wrapper
    result = func(*args, **kwargs)
  File "c:\users\beaso\pycharmprojects\g89.2022.t10.eg4\src\unittest\python\test_vaccine_patient_tests.py", line 122, in test_vaccine_patient_not_found_date_signature
    my_manager.vaccine_patient(
  File "c:\users\beaso\pycharmprojects\g89.2022.t10.eg4\src\main\python\uc3m_care\vaccine_manager.py", line 36, in vaccine_patient
    appointment = VaccinationAppoinment.get_appointment_from_date_signature(date_signature)
  File "c:\users\beaso\pycharmprojects\g89.2022.t10.eg4\src\main\python\uc3m_care\data\vaccination_appointment.py", line 49, in get_appointment_from_date_signature
    appointment_record = appointments_store.find_item(date_signature)
  File "c:\users\beaso\pycharmprojects\g89.2022.t10.eg4\src\main\python\uc3m_care\storage\json_store.py", line 39, in find_item
    if item[key] == key_value:
KeyError: 'VaccinationAppointment__date_signature'
]]></error>
	</testcase>
	<testcase classname="test_vaccine_patient_tests.TestVaccinePatient" name="test_vaccine_patient_ok" time="0.037" timestamp="2022-04-26T16:15:14">
		<error type="KeyError" message="'VaccinationAppointment__date_signature'"><![CDATA[Traceback (most recent call last):
  File "C:\Users\beaso\AppData\Local\Programs\Python\Python310\lib\unittest\case.py", line 59, in testPartExecutor
    yield
  File "C:\Users\beaso\AppData\Local\Programs\Python\Python310\lib\unittest\case.py", line 591, in run
    self._callTestMethod(testMethod)
  File "C:\Users\beaso\AppData\Local\Programs\Python\Python310\lib\unittest\case.py", line 549, in _callTestMethod
    method()
  File "C:\Users\beaso\AppData\Local\Programs\Python\Python310\lib\site-packages\freezegun\api.py", line 789, in wrapper
    result = func(*args, **kwargs)
  File "c:\users\beaso\pycharmprojects\g89.2022.t10.eg4\src\unittest\python\test_vaccine_patient_tests.py", line 46, in test_vaccine_patient_ok
    signature = my_manager.vaccine_patient(
  File "c:\users\beaso\pycharmprojects\g89.2022.t10.eg4\src\main\python\uc3m_care\vaccine_manager.py", line 36, in vaccine_patient
    appointment = VaccinationAppoinment.get_appointment_from_date_signature(date_signature)
  File "c:\users\beaso\pycharmprojects\g89.2022.t10.eg4\src\main\python\uc3m_care\data\vaccination_appointment.py", line 49, in get_appointment_from_date_signature
    appointment_record = appointments_store.find_item(date_signature)
  File "c:\users\beaso\pycharmprojects\g89.2022.t10.eg4\src\main\python\uc3m_care\storage\json_store.py", line 39, in find_item
    if item[key] == key_value:
KeyError: 'VaccinationAppointment__date_signature'
]]></error>
	</testcase>
</testsuite>
